{
 "cells": [
  {
   "cell_type": "code",
   "execution_count": 24,
   "metadata": {},
   "outputs": [],
   "source": [
    "import pandas as pd"
   ]
  },
  {
   "cell_type": "code",
   "execution_count": 15,
   "metadata": {},
   "outputs": [],
   "source": [
    "df = pd.DataFrame = ({'street_number': 104, 'street_name':'PUTNAM', \n",
    "                 'num_bedrooms' :15, 'owner_occupied':'Yes'},\n",
    "                    {'street_number':197, 'street_name': 'LEXINGTON',\n",
    "                    'num_bedrooms': 3, 'owner_occupied': 'No'})"
   ]
  },
  {
   "cell_type": "code",
   "execution_count": 16,
   "metadata": {},
   "outputs": [
    {
     "data": {
      "text/plain": [
       "({'street_number': 104,\n",
       "  'street_name': 'PUTNAM',\n",
       "  'num_bedrooms': 15,\n",
       "  'owner_occupied': 'Yes'},\n",
       " {'street_number': 197,\n",
       "  'street_name': 'LEXINGTON',\n",
       "  'num_bedrooms': 3,\n",
       "  'owner_occupied': 'No'})"
      ]
     },
     "execution_count": 16,
     "metadata": {},
     "output_type": "execute_result"
    }
   ],
   "source": [
    "df"
   ]
  },
  {
   "cell_type": "code",
   "execution_count": 19,
   "metadata": {},
   "outputs": [
    {
     "ename": "TypeError",
     "evalue": "'tuple' object is not callable",
     "output_type": "error",
     "traceback": [
      "\u001b[0;31m---------------------------------------------------------------------------\u001b[0m",
      "\u001b[0;31mTypeError\u001b[0m                                 Traceback (most recent call last)",
      "\u001b[0;32m<ipython-input-19-55628a451755>\u001b[0m in \u001b[0;36m<module>\u001b[0;34m()\u001b[0m\n\u001b[1;32m      4\u001b[0m \u001b[0mcols\u001b[0m \u001b[0;34m=\u001b[0m \u001b[0;34m[\u001b[0m\u001b[0;34m'street_number, street_name, num_bedrooms, owner_occupied'\u001b[0m\u001b[0;34m]\u001b[0m\u001b[0;34m\u001b[0m\u001b[0m\n\u001b[1;32m      5\u001b[0m \u001b[0;34m\u001b[0m\u001b[0m\n\u001b[0;32m----> 6\u001b[0;31m \u001b[0mc\u001b[0m \u001b[0;34m=\u001b[0m \u001b[0mpd\u001b[0m\u001b[0;34m.\u001b[0m\u001b[0mDataFrame\u001b[0m\u001b[0;34m(\u001b[0m\u001b[0mdata\u001b[0m\u001b[0;34m,\u001b[0m \u001b[0mcolumns\u001b[0m\u001b[0;34m=\u001b[0m\u001b[0mcols\u001b[0m\u001b[0;34m)\u001b[0m\u001b[0;34m\u001b[0m\u001b[0m\n\u001b[0m",
      "\u001b[0;31mTypeError\u001b[0m: 'tuple' object is not callable"
     ]
    }
   ],
   "source": [
    "data = [[\"104\", \"PUTNAM\", 15, \"Yes\"],\n",
    "     [\"197\", \"LEXINGTON\", 3, \"No\"]]\n",
    "\n",
    "cols = ['street_number, street_name, num_bedrooms, owner_occupied']\n",
    "\n",
    "c = pd.DataFrame(data, columns=cols)"
   ]
  },
  {
   "cell_type": "code",
   "execution_count": 29,
   "metadata": {},
   "outputs": [
    {
     "ename": "TypeError",
     "evalue": "'tuple' object is not callable",
     "output_type": "error",
     "traceback": [
      "\u001b[0;31m---------------------------------------------------------------------------\u001b[0m",
      "\u001b[0;31mTypeError\u001b[0m                                 Traceback (most recent call last)",
      "\u001b[0;32m<ipython-input-29-fa44dab4a229>\u001b[0m in \u001b[0;36m<module>\u001b[0;34m()\u001b[0m\n\u001b[1;32m      8\u001b[0m \u001b[0mcols\u001b[0m \u001b[0;34m=\u001b[0m \u001b[0;34m[\u001b[0m\u001b[0;34m\"revenue\"\u001b[0m\u001b[0;34m,\u001b[0m \u001b[0;34m\"fy\"\u001b[0m\u001b[0;34m,\u001b[0m \u001b[0;34m\"employees\"\u001b[0m\u001b[0;34m,\u001b[0m \u001b[0;34m\"mcap\"\u001b[0m\u001b[0;34m,\u001b[0m \u001b[0;34m\"location\"\u001b[0m\u001b[0;34m]\u001b[0m\u001b[0;34m\u001b[0m\u001b[0m\n\u001b[1;32m      9\u001b[0m \u001b[0;34m\u001b[0m\u001b[0m\n\u001b[0;32m---> 10\u001b[0;31m \u001b[0mc\u001b[0m \u001b[0;34m=\u001b[0m \u001b[0mpd\u001b[0m\u001b[0;34m.\u001b[0m\u001b[0mDataFrame\u001b[0m\u001b[0;34m(\u001b[0m\u001b[0mdata\u001b[0m\u001b[0;34m,\u001b[0m \u001b[0mindex\u001b[0m\u001b[0;34m=\u001b[0m\u001b[0mcomps\u001b[0m\u001b[0;34m,\u001b[0m \u001b[0mcolumns\u001b[0m\u001b[0;34m=\u001b[0m\u001b[0mcols\u001b[0m\u001b[0;34m)\u001b[0m\u001b[0;34m\u001b[0m\u001b[0m\n\u001b[0m",
      "\u001b[0;31mTypeError\u001b[0m: 'tuple' object is not callable"
     ]
    }
   ],
   "source": [
    "data = [[\"$229.2\", 2017, 123000, \"$1100\", \"Cupertino, US\"],\n",
    "     [\"$211.9\", 2017, 320671, \"$284\", \"Suwon, South Korea\"],\n",
    "     [\"$177.8\", 2017, 566000, \"$985\",  \"Seattle, US\"],\n",
    "     [\"$154.7\", 2017, 1300000, \"$66\", \"New Taipei City, Taiwan\"],\n",
    "     [\"$110.8\", 2017, 80110, \"$834\", \"Mountain View, US\"]]\n",
    "\n",
    "comps = [\"apple\", \"samsung\", \"amazon\", \"foxconn\", \"alphabet\"]\n",
    "cols = [\"revenue\", \"fy\", \"employees\", \"mcap\", \"location\"]\n",
    "\n",
    "c = pd.DataFrame(data, index=comps, columns=cols)\n"
   ]
  },
  {
   "cell_type": "code",
   "execution_count": 21,
   "metadata": {},
   "outputs": [
    {
     "ename": "TypeError",
     "evalue": "'tuple' object is not callable",
     "output_type": "error",
     "traceback": [
      "\u001b[0;31m---------------------------------------------------------------------------\u001b[0m",
      "\u001b[0;31mTypeError\u001b[0m                                 Traceback (most recent call last)",
      "\u001b[0;32m<ipython-input-21-757db31a85c9>\u001b[0m in \u001b[0;36m<module>\u001b[0;34m()\u001b[0m\n\u001b[1;32m      1\u001b[0m pd.DataFrame([[\"104\", \"PUTNAM\", 15, \"Yes\"], [\"197\", \"LEXINGTON\", 3, \"No\"]], \n\u001b[0;32m----> 2\u001b[0;31m     columns=['street_number, street_name, num_bedrooms, owner_occupied'])\n\u001b[0m",
      "\u001b[0;31mTypeError\u001b[0m: 'tuple' object is not callable"
     ]
    }
   ],
   "source": [
    "pd.DataFrame([[\"104\", \"PUTNAM\", 15, \"Yes\"], [\"197\", \"LEXINGTON\", 3, \"No\"]], \n",
    "    columns=['street_number, street_name, num_bedrooms, owner_occupied'])"
   ]
  },
  {
   "cell_type": "code",
   "execution_count": 25,
   "metadata": {},
   "outputs": [
    {
     "ename": "TypeError",
     "evalue": "'tuple' object is not callable",
     "output_type": "error",
     "traceback": [
      "\u001b[0;31m---------------------------------------------------------------------------\u001b[0m",
      "\u001b[0;31mTypeError\u001b[0m                                 Traceback (most recent call last)",
      "\u001b[0;32m<ipython-input-25-f1c924a4d0ca>\u001b[0m in \u001b[0;36m<module>\u001b[0;34m()\u001b[0m\n\u001b[1;32m      1\u001b[0m pd.DataFrame([[1, 2, 3], [4, 5, 6]], \n\u001b[0;32m----> 2\u001b[0;31m     columns=['A', 'B', 'C'])\n\u001b[0m",
      "\u001b[0;31mTypeError\u001b[0m: 'tuple' object is not callable"
     ]
    }
   ],
   "source": [
    "pd.DataFrame([[1, 2, 3], [4, 5, 6]], \n",
    "    columns=['A', 'B', 'C'])"
   ]
  },
  {
   "cell_type": "code",
   "execution_count": null,
   "metadata": {},
   "outputs": [],
   "source": []
  },
  {
   "cell_type": "code",
   "execution_count": 27,
   "metadata": {},
   "outputs": [
    {
     "ename": "TypeError",
     "evalue": "'tuple' object is not callable",
     "output_type": "error",
     "traceback": [
      "\u001b[0;31m---------------------------------------------------------------------------\u001b[0m",
      "\u001b[0;31mTypeError\u001b[0m                                 Traceback (most recent call last)",
      "\u001b[0;32m<ipython-input-27-89b765d73665>\u001b[0m in \u001b[0;36m<module>\u001b[0;34m()\u001b[0m\n\u001b[0;32m----> 1\u001b[0;31m \u001b[0mdf1\u001b[0m \u001b[0;34m=\u001b[0m \u001b[0mpd\u001b[0m\u001b[0;34m.\u001b[0m\u001b[0mDataFrame\u001b[0m\u001b[0;34m(\u001b[0m\u001b[0;34m[\u001b[0m\u001b[0;34m[\u001b[0m\u001b[0;36m1\u001b[0m\u001b[0;34m,\u001b[0m \u001b[0;36m2\u001b[0m\u001b[0;34m,\u001b[0m \u001b[0;36m3\u001b[0m\u001b[0;34m]\u001b[0m\u001b[0;34m,\u001b[0m \u001b[0;34m[\u001b[0m\u001b[0;36m4\u001b[0m\u001b[0;34m,\u001b[0m \u001b[0;36m5\u001b[0m\u001b[0;34m,\u001b[0m \u001b[0;36m6\u001b[0m\u001b[0;34m]\u001b[0m\u001b[0;34m]\u001b[0m\u001b[0;34m,\u001b[0m \u001b[0mcolumns\u001b[0m\u001b[0;34m=\u001b[0m\u001b[0;34m[\u001b[0m\u001b[0;34m'A'\u001b[0m\u001b[0;34m,\u001b[0m \u001b[0;34m'B'\u001b[0m\u001b[0;34m,\u001b[0m \u001b[0;34m'C'\u001b[0m\u001b[0;34m]\u001b[0m\u001b[0;34m)\u001b[0m\u001b[0;34m\u001b[0m\u001b[0m\n\u001b[0m",
      "\u001b[0;31mTypeError\u001b[0m: 'tuple' object is not callable"
     ]
    }
   ],
   "source": [
    "df1 = pd.DataFrame([[1, 2, 3], [4, 5, 6]], columns=['A', 'B', 'C'])"
   ]
  },
  {
   "cell_type": "code",
   "execution_count": null,
   "metadata": {},
   "outputs": [],
   "source": []
  }
 ],
 "metadata": {
  "kernelspec": {
   "display_name": "Python 3",
   "language": "python",
   "name": "python3"
  },
  "language_info": {
   "codemirror_mode": {
    "name": "ipython",
    "version": 3
   },
   "file_extension": ".py",
   "mimetype": "text/x-python",
   "name": "python",
   "nbconvert_exporter": "python",
   "pygments_lexer": "ipython3",
   "version": "3.7.0"
  }
 },
 "nbformat": 4,
 "nbformat_minor": 2
}
